Workbook
Name data: #REF!
Name data: #REF!
Name data: #REF!
Name data: #REF!
Name data: #REF!
Name data: #REF!
Name data: #REF!
Name data: #REF!
Name data: #REF!

Sheet لوحة الربحية
A1: لوحة الربحية والتكلفة – مشروع سبارك
A2: نسخة إدارية قابلة للتحديث – جميع القيم بالريال السعودي، والمصروفات الإضافية تُسجل في ورقة «المصروفات الإضافية».
A5: قيمة العقد الأصلية | B5: =6493121.74 -> 6493121.7 | D5: قراءة سريعة
A6: أوامر التغيير | B6: =27918 -> 27918 | D6: نسبة الإنجاز التعاقدية | E6: =IFERROR(B8/B7,0) -> 0.89523428
A7: قيمة العقد المعدلة | B7: =B5+B6 -> 6521039.7 | D7: نسبة التكلفة المباشرة من قيمة الأعمال | E7: =IFERROR(B11/B8,0) -> 0.67354787
A8: قيمة الأعمال المنجزة | B8: =summary!K44 -> 5837858.3 | D8: نقطة الانتباه | E8: أدخل المصروفات غير المباشرة أولاً بأول
A9: تكلفة المواد المباشرة | B9: ='ملخص التكاليف'!B37 -> 3104507 | D9: النتيجة الحالية | E9: الربح الصافي يتغير تلقائياً بعد تسجيل المصروفات
A10: تكلفة العمالة المباشرة | B10: ='ملخص التكاليف'!C37 -> 827570
A11: إجمالي التكلفة المباشرة | B11: ='ملخص التكاليف'!D37 -> 3932077
A12: الربح الفعلي حسب Profit | B12: ='ملخص التكاليف'!G37 -> 2483848.9 | D12: البند | E12: القيمة
A13: المصروفات الإضافية | B13: ='ملخص التكاليف'!B52 -> 549500 | D13: قيمة الأعمال المنجزة | E13: =B8 -> 5837858.3
A14: الربح الصافي بعد المصروفات الإضافية | B14: =B12-B13 -> 1934348.9 | D14: التكلفة المباشرة | E14: =B11 -> 3932077
A15: هامش الربح الصافي | B15: =IFERROR(B14/B8,0) -> 0.33134563 | D15: الربح قبل المصروفات | E15: =B12 -> 2483848.9
D16: المصروفات الإضافية | E16: =B13 -> 549500
D17: الربح بعد المصروفات | E17: =E15-E16 -> 1934348.9

Sheet INVOICE NO 14
AA3: Affordable House Co.
AA4: CONTRACTORS PAYMENT CERTIFICATE
N7: Interim Advance Payment | AT7: Interim Progress Payment | BZ7: Interim Exchange of Retention
N9: Final Pay and Release of Retention
B11: Contract No. | J11: : | K11: C/AHC/PD/C070/2024 | BF11: Contractor's Payment Certificate No. | CC11: : | CD11: 14
B12: Consultant | J12: : | K12: شركة المسكن الميسر | BS12: Certificate Date | CC12: : | CD12: 46026
B13: Contractor | J13: : | K13: مؤسسة أسس السلامة لأجهزة السلامة | BS13: Valuation Date | CC13: :
B14: Project Title | J14: : | K14: عقد تنفيذ اعمال إنذار ومكافحة الحريق للمباني وغرف المضخات بالمرحلة الاول PHASE 1مجمع سكن العمال (ECODAN) في مدينة الملك سلمان للطاقة
B17: Original Contract Value | AR17: SR | AU17: القيمة الأصلية للعقد | CF17: 6493121.7
AU18: أمر تغيير رقم (1) | CF18: 27918
AU20: قيمة الدفعة المقدمة | CF20: =CF17*0.1 -> 649312.17
B21: Revised Contract Value | AR21: SR | AU21: اجمالي قيمة العقد | CF21: =CF17+CF18 -> 6521039.7
B23: Description | BJ23: Cumulative To Date (SR) | BV23: Cumulative Previous (SR) | CH23: This Payment (SR)
B24: Deserved against Original Contract and Variation Order:
B25: دفعة أولى صرفت مسبقاً | BI25: 0.1 | BJ25: 649312.17 | BV25: 649312.17 | CH25: 0
B26: قيمة الاعمال المنجزة حتى تاريخه | BI26: =BJ26/CF21 -> 0.89523428 | BJ26: =BV26+CH26 -> 5837858.3 | BV26: =summary!I44 -> 4918609.4 | CH26: =summary!J44 -> 919248.94
B27: أمر تغيير رقم (1) | BJ27: 27918 | BV27: 27918
B31: Total Gross Certified | BG31: =BI26+BI25 -> 0.99523428 | BJ31: =SUM(BJ24:BU30) -> 6515088.5 | BV31: =SUM(BV24:CG30) -> 5595839.5 | CH31: =SUM(CH25:CS30) -> 919248.94
B32: Deductions:
B34: On Hold - Best Performance =10% | BJ34: =BV34+CH34 -> 651508.85 | BV34: =BV31*0.1 -> 559583.95 | CH34: =CH31*0.1 -> 91924.894
B35: قيمة غرامة التاخير طبقا للعقد في زون 1 | BJ35: =BV35+CH35 -> 42781.6 | BV35: 42781.6 | CH35: 0
B36: استرداد خصم الاستشاري | BJ36: =BV36+CH36 -> -2037.22 | BV36: -2037.22 | CH36: 0
B38: Total Deductions | BJ38: =SUM(BJ33:BU37) -> 692253.23 | BV38: =SUM(BV33:CG37) -> 600328.33 | CH38: =SUM(CH33:CS37) -> 91924.894
B40: AMOUNT CERTIFIED THIS PAYMENT CERTIFICATE | BJ40: =BJ31-BJ38 -> 5822835.2 | BV40: =BV31-BV38 -> 4995511.2 | CH40: =CH31-CH38 -> 827324.04
B41: مائة وإثنان الفا وخمسمائة وخمسة وتسعون ريالا وست وأربعون هللة لا غير
B44: إقرار: إن المقاول يقر بأن قيمة الأعمال الواردة أعلاه في المستخلص هي كل ما لديه من مستحقات لدى شركة المسكن الميسر حتى تاريخ المستخلص، وعلى هذا يوقع
B46: Submitted by Contractor | R46: : | AD46: (مؤسسة أسس السلامة لأجهزة السلامة) | BJ46: Stamp:
J49: Project Manager
B51: Reviewed by consultant | R51: : | AD51: (مكتب التأثير للاستشارات الهندسية IMPACT) | BJ51: Stamp:
J54: Resident Engineer
B56: Certified for Payment by Project Manager | AB56: : | AD56: (شركة المسكن الميسر Affordable House)
D59: Project Manager/ Client Representative | BI59: Acting / Projects Dept. Director
B61: Approved for Payment by Client | W61: : | AD61: (شركة المسكن الميسر Affordable House)
BI64: Acting/CEO

Sheet summary
A7: PAY ITEM NO. | B7: DESCRIPTION OF ITEM | F7: PREVIOUS PRICE (SR) EXCL. VAT | G7: CURRENT PRICE (SR) EXCL. VAT | H7: EXTENDED PRICE (SR) EXCL. VAT | I7: 90% OF PREVIOUS Amount | J7: 90% OF Current Amount | K7: 90% OF CUMULATIVE (10% ADV. PAYMENT)
A10: JUN-T1 | B10: SUB-TOTAL ITEM NO. B1-21 00 00 | C10: xxx | D10: xxx | E10: xxx | F10: 730383.57 | G10: ='JUN-T1'!J39 -> 29111.882 | H10: =G10+F10 -> 759495.45 | I10: =0.9*F10 -> 657345.21 | J10: =0.9*G10 -> 26200.694 | K10: =0.9*H10 -> 683545.91
A11: JUN-T2 | B11: SUB-TOTAL ITEM NO. B2-21 00 00 | C11: xxx | D11: xxx | E11: xxx | F11: 291679.97 | G11: ='JUN-T2'!J39 -> 6391.33 | H11: =G11+F11 -> 298071.3 | I11: =0.9*F11 -> 262511.97 | J11: =0.9*G11 -> 5752.197 | K11: =0.9*H11 -> 268264.17
A12: SUPRVSR | B12: SUB-TOTAL ITEM NO. B3-21 00 00 | C12: xxx | D12: xxx | E12: xxx | F12: 431679.7 | G12: =SUPERVISOR!J39 -> 15034.399 | H12: =G12+F12 -> 446714.1 | I12: =0.9*F12 -> 388511.73 | J12: =0.9*G12 -> 13530.959 | K12: =0.9*H12 -> 402042.69
A13: SENIOR | B13: SUB-TOTAL ITEM NO. B4-21 00 00 | C13: xxx | D13: xxx | E13: xxx | F13: 475707.15 | G13: =SENIOR!J39 -> 16490.251 | H13: =G13+F13 -> 492197.4 | I13: =0.9*F13 -> 428136.43 | J13: =0.9*G13 -> 14841.226 | K13: =0.9*H13 -> 442977.66
A14: ISOLATED | B14: SUB-TOTAL ITEM NO. B6-21 00 00 | C14: xxx | D14: xxx | E14: xxx | F14: 106713.7 | G14: =ISOLATED!J39 -> 7644.4488 | H14: =G14+F14 -> 114358.15 | I14: =0.9*F14 -> 96042.331 | J14: =0.9*G14 -> 6880.0039 | K14: =0.9*H14 -> 102922.33
A15: ADMIN | B15: SUB-TOTAL ITEM NO. B7-21 00 00 | C15: xxx | D15: xxx | E15: xxx | F15: 131017.9 | G15: =ADMIN!J27 -> 25772.9 | H15: =G15+F15 -> 156790.8 | I15: =0.9*F15 -> 117916.11 | J15: =0.9*G15 -> 23195.61 | K15: =0.9*H15 -> 141111.72
A16: RECREATN | B16: SUB-TOTAL ITEM NO. B8-21 00 00 | C16: xxx | D16: xxx | E16: xxx | F16: 198733.96 | G16: =RECREATION!J41 -> 36418.286 | H16: =G16+F16 -> 235152.25 | I16: =0.9*F16 -> 178860.57 | J16: =0.9*G16 -> 32776.458 | K16: =0.9*H16 -> 211637.02
A17: SERVICE | B17: SUB-TOTAL ITEM NO. B9-21 00 00 | C17: xxx | D17: xxx | E17: xxx | F17: 428538.46 | G17: =SERVICE!J45 -> 307168.39 | H17: =G17+F17 -> 735706.85 | I17: =0.9*F17 -> 385684.61 | J17: =0.9*G17 -> 276451.55 | K17: =0.9*H17 -> 662136.17
A18: PUMP RM-2 | B18: SUB-TOTAL ITEM NO. B12-21 00 00 | C18: xxx | D18: xxx | E18: xxx | F18: 439932.46 | G18: =PUMP02!J48 -> 101885.29 | H18: =G18+F18 -> 541817.75 | I18: =0.9*F18 -> 395939.21 | J18: =0.9*G18 -> 91696.761 | K18: =0.9*H18 -> 487635.98
A19: JUN-T1 - E | B19: SUB-TOTAL ITEM NO. B1-2800 00 | C19: xxx | D19: xxx | E19: xxx | F19: 699685.54 | G19: ='JUN-T1 E'!I36 -> 122738.66 | H19: =G19+F19 -> 822424.2 | I19: =0.9*F19 -> 629716.99 | J19: =0.9*G19 -> 110464.79 | K19: =0.9*H19 -> 740181.78
A20: JUN-T2 - E | B20: SUB-TOTAL ITEM NO. B2-28 00 00 | C20: xxx | D20: xxx | E20: xxx | F20: 191301.46 | G20: ='JUN-T2 E'!I35 -> 26967.94 | H20: =G20+F20 -> 218269.4 | I20: =0.9*F20 -> 172171.31 | J20: =0.9*G20 -> 24271.146 | K20: =0.9*H20 -> 196442.46
A21: SUPRVSR - E | B21: SUB-TOTAL ITEM NO. B3-28 00 00 | C21: xxx | D21: xxx | E21: xxx | F21: 282927.66 | G21: ='SUPERVISOR -E'!I33 -> 62809.44 | H21: =G21+F21 -> 345737.1 | I21: =0.9*F21 -> 254634.89 | J21: =0.9*G21 -> 56528.496 | K21: =0.9*H21 -> 311163.39
A22: SENIOR - E | B22: SUB-TOTAL ITEM NO. B4-28 00 00 | C22: xxx | D22: xxx | E22: xxx | F22: 361496.21 | G22: ='SENIOR - E'!J35 -> 45496.395 | H22: =G22+F22 -> 406992.6 | I22: =0.9*F22 -> 325346.58 | J22: =0.9*G22 -> 40946.756 | K22: =0.9*H22 -> 366293.34
A23: ISOLATED - E | B23: SUB-TOTAL ITEM NO. B6-28 00 00 | C23: xxx | D23: xxx | E23: xxx | F23: 105596.24 | G23: ='ISOLATE - E'!I34 -> -11312.237 | H23: =G23+F23 -> 94284 | I23: =0.9*F23 -> 95036.613 | J23: =0.9*G23 -> -10181.013 | K23: =0.9*H23 -> 84855.6
A24: ADMIN - E | B24: SUB-TOTAL ITEM NO. B7-28 00 00 | C24: xxx | D24: xxx | E24: xxx | F24: 67078.41 | G24: ='ADMIN -E'!J35 -> 79168.49 | H24: =G24+F24 -> 146246.9 | I24: =0.9*F24 -> 60370.569 | J24: =0.9*G24 -> 71251.641 | K24: =0.9*H24 -> 131622.21
A25: RECREATN - E | B25: SUB-TOTAL ITEM NO. B8-28 00 00 | C25: xxx | D25: xxx | E25: xxx | F25: 131764.8 | G25: ='RECREATION - E'!J36 -> 18517.3 | H25: =G25+F25 -> 150282.1 | I25: =0.9*F25 -> 118588.32 | J25: =0.9*G25 -> 16665.57 | K25: =0.9*H25 -> 135253.89
A26: SERVICE - E | B26: SUB-TOTAL ITEM NO. B9-28 00 00 | C26: xxx | D26: xxx | E26: xxx | F26: 187954.48 | G26: ='SERVICE - E'!J36 -> 109690.03 | H26: =G26+F26 -> 297644.5 | I26: =0.9*F26 -> 169159.03 | J26: =0.9*G26 -> 98721.023 | K26: =0.9*H26 -> 267880.05
A27: GUARD RM | B27: SUB-TOTAL ITEM NO. B10-28 00 00 | C27: xxx | D27: xxx | E27: xxx | F27: 27603.775 | G27: ='GUARD RM'!I31 -> 18762.225 | H27: =G27+F27 -> 46366 | I27: =0.9*F27 -> 24843.398 | J27: =0.9*G27 -> 16886.002 | K27: =0.9*H27 -> 41729.4
A28: PUMP RM-1 | B28: SUB-TOTAL ITEM NO. B11-28 00 00 | C28: xxx | D28: xxx | E28: xxx | F28: 0 | G28: ='PUMP RM-1'!K19 -> 2910 | H28: =G28+F28 -> 2910 | I28: =0.9*F28 -> 0 | J28: =0.9*G28 -> 2619 | K28: =0.9*H28 -> 2619
A29: PUMP RM-2 | B29: SUB-TOTAL ITEM NO. B12-28 00 00 | C29: xxx | D29: xxx | E29: xxx | F29: 0 | G29: ='PUMP RM-2'!K22 -> 11640 | H29: =G29+F29 -> 11640 | I29: =0.9*F29 -> 0 | J29: =0.9*G29 -> 10476 | K29: =0.9*H29 -> 10476
A30: PUMP RM-3 | B30: SUB-TOTAL ITEM NO. B13-28 00 00 | C30: xxx | D30: xxx | E30: xxx | F30: 0 | G30: ='PUMP RM-3'!J19 -> 2910 | H30: =G30+F30 -> 2910 | I30: =0.9*F30 -> 0 | J30: =0.9*G30 -> 2619 | K30: =0.9*H30 -> 2619
A31: JUN-T1-EXT | B31: SUB-TOTAL ITEM NO. B1-10 00 00 | C31: xxx | D31: xxx | E31: xxx | F31: 76242 | G31: ='JUN-T1-EXT'!J20 -> 0 | H31: =G31+F31 -> 76242 | I31: =0.9*F31 -> 68617.8 | J31: =0.9*G31 -> 0 | K31: =0.9*H31 -> 68617.8
A32: JUN-T2-EXT | B32: SUB-TOTAL ITEM NO. B2-10 00 00 | C32: xxx | D32: xxx | E32: xxx | F32: 11441.65 | G32: ='JUN-T2-EXT'!J20 -> 4175.85 | H32: =G32+F32 -> 15617.5 | I32: =0.9*F32 -> 10297.485 | J32: =0.9*G32 -> 3758.265 | K32: =0.9*H32 -> 14055.75
A33: SUPERVISOR-EXT | B33: SUB-TOTAL ITEM NO. B3-10 00 00 | C33: xxx | D33: xxx | E33: xxx | F33: 19999.225 | G33: ='SUPERVISOR-EXT '!J20 -> 7670.275 | H33: =G33+F33 -> 27669.5 | I33: =0.9*F33 -> 17999.302 | J33: =0.9*G33 -> 6903.2475 | K33: =0.9*H33 -> 24902.55
A34: SENIOR-EXT | B34: SUB-TOTAL ITEM NO. B4-10 00 00 | C34: xxx | D34: xxx | E34: xxx | F34: 15447 | G34: ='SENIOR-EXT'!J15 -> 2500 | H34: =G34+F34 -> 17947 | I34: =0.9*F34 -> 13902.3 | J34: =0.9*G34 -> 2250 | K34: =0.9*H34 -> 16152.3
A35: ISOLATED-EXT | B35: SUB-TOTAL ITEM NO. B6-10 00 00 | C35: xxx | D35: xxx | E35: xxx | F35: 5322.95 | G35: ='ISOLATED-EXT '!J20 -> 2048.05 | H35: =G35+F35 -> 7371 | I35: =0.9*F35 -> 4790.655 | J35: =0.9*G35 -> 1843.245 | K35: =0.9*H35 -> 6633.9
A36: ADMIN-EXT | B36: SUB-TOTAL ITEM NO. B7-10 00 00 | C36: xxx | D36: xxx | E36: xxx | F36: 2863.8 | G36: ='ADMIN-EXT'!J21 -> 2192.2 | H36: =G36+F36 -> 5056 | I36: =0.9*F36 -> 2577.42 | J36: =0.9*G36 -> 1972.98 | K36: =0.9*H36 -> 4550.4
A37: RECREATION-EXT | B37: SUB-TOTAL ITEM NO. B8-10 00 00 | C37: xxx | D37: xxx | E37: xxx | F37: 10628 | G37: ='RECREATION-EXT'!J17 -> 4285 | H37: =G37+F37 -> 14913 | I37: =0.9*F37 -> 9565.2 | J37: =0.9*G37 -> 3856.5 | K37: =0.9*H37 -> 13421.7
A38: SERVICE-EXT | B38: SUB-TOTAL ITEM NO. B9-10 00 00 | C38: xxx | D38: xxx | E38: xxx | F38: 21367.5 | G38: ='SERVICE-EXT'!J22 -> 14557.5 | H38: =G38+F38 -> 35925 | I38: =0.9*F38 -> 19230.75 | J38: =0.9*G38 -> 13101.75 | K38: =0.9*H38 -> 32332.5
A39: GUARD-RM-EXT | B39: SUB-TOTAL ITEM NO. B10-10 00 00 | C39: xxx | D39: xxx | E39: xxx | F39: 434.2 | G39: ='GUARD-RM-EXT'!J14 -> 196.425 | H39: =G39+F39 -> 630.625 | I39: =0.9*F39 -> 390.78 | J39: =0.9*G39 -> 176.7825 | K39: =0.9*H39 -> 567.5625
A40: PUMP-R1-EXT | B40: SUB-TOTAL ITEM NO. B11-10 00 00 | C40: xxx | D40: xxx | E40: xxx | F40: 5761.925 | G40: ='PUMP-R1-EXT'!J16 -> 10631.2 | H40: =G40+F40 -> 16393.125 | I40: =0.9*F40 -> 5185.7325 | J40: =0.9*G40 -> 9568.08 | K40: =0.9*H40 -> 14753.812
A41: PUMP-R21-EXT | B41: SUB-TOTAL ITEM NO. B12-10 00 00 | C41: xxx | D41: xxx | E41: xxx | F41: 465.725 | G41: ='PUMP-R2-EXT'!J15 -> 196.425 | H41: =G41+F41 -> 662.15 | I41: =0.9*F41 -> 419.1525 | J41: =0.9*G41 -> 176.7825 | K41: =0.9*H41 -> 595.935
A42: PUMP-R3-EXT | B42: SUB-TOTAL ITEM NO. B13-10 00 00 | C42: xxx | D42: xxx | E42: xxx | F42: 5352.1 | G42: ='PUMP-R3-EXT'!J16 -> 2844.525 | H42: =G42+F42 -> 8196.625 | I42: =0.9*F42 -> 4816.89 | J42: =0.9*G42 -> 2560.0725 | K42: =0.9*H42 -> 7376.9625
A43: Variance between the total quantities amount and the contract amount | H43: =-59512.64 -> -59512.64 | J43: =H43 -> -59512.64 | K43: =J43 -> -59512.64
B44: TOTAL ESTIMATED CONTRACT PRICE FOR PAY ITEM NO. B1 | C44: xxx | D44: xxx | E44: xxx | F44: =SUM(F9:F43) -> 5465121.5 | G44: =SUM(G9:G43) -> 1087512.9 | H44: =SUM(H9:H43) -> 6493121.7 | I44: =SUM(I9:I43) -> 4918609.4 | J44: =SUM(J10:J43) -> 919248.94 | K44: =SUM(K9:K43) -> 5837858.3
B46: % of Completion | H46: =H44/6493121.74 -> 1
H49: 6493121.7
H50: =H44-H49 -> -0.0049999999
H52: =H43-H50 -> -59512.635

Sheet JUN-T1 E
B4: JUN T1 E
B5: B O Q | E5: THE ACTUAL QTY | H5: AMOUNT (SR)
A6: DESCRIPTION OF ITEM | B6: ESTIMATED QUANTITY | C6: UNIT | D6: UNIT PRICE(SR) EXCL. VAT | E6: Previous QTY | F6: Current QTY | G6: Cumulative QTY | H6: Previous | I6: Current | J6: Cumulative | K6: Percentage | L6: Actual price | M6: Actual Labour charge | N6: Total AP+LC | O6: Profit
A8: DIVISION 28-ELECTRONIC SAFETY AND SECURITY
A9: Supply and installation of IP Fixed cameras, POE+ TCP/IP and IP Indoor fixed mini dome camera-ceiling mounted, including all accessories, testing, commissioning and configuration of the network and other Works as shown on the Contract drawings and specified in the Contract documents.
A10: Fire Detection and Alarm
A11: Fire alarm control panel (FACP)
A12: Supply, installation, testing and commissioning of a microprocessor based, addressable fire alarm control panel, complete with Chassis, 640-Character backlit LCD display, QWERTY programming and control keypad, loop cards, zone and input/output modules, supervisory devices, auxiliary relays, network capability modules, battery, battery charger, printer, internal alarm, interface contacts and all accessories and hardware as shown on the Contract drawings and specified in the Contract documents and to complete the fully functional, operable, reliable and maintainable fire alarm system.
A13: Microprocessor based, addressable FACP,5 loop type | B13: 12 | C13: Ea | D13: 22795 | E13: 10.8 | F13: =B13-E13 -> 1.2 | G13: =E13+F13 -> 12 | H13: =E13*D13 -> 246186 | I13: =F13*D13 -> 27354 | J13: =H13+I13 -> 273540 | K13: =G13/B13 -> 1 | L13: 16900 | M13: 80 | N13: =B13*(L13+M13) -> 203760 | O13: =J13-N13 -> 69780
A14: Power supply unit, batteries and battery chargers | B14: 12 | C14: Ea | D14: 4365 | E14: 0 | F14: =B14-E14 -> 12 | G14: =E14+F14 -> 12 | H14: =E14*D14 -> 0 | I14: =F14*D14 -> 52380 | J14: =H14+I14 -> 52380 | K14: =G14/B14 -> 1 | L14: 0 | M14: 0 | N14: =B14*(L14+M14) -> 0 | O14: =J14-N14 -> 52380
A15: Supply, selection and calculation, installation, testing and commissioning of FACP power supply unit, batteries for at least 24 hours during the normal operations and 15 mins under emergency full loaded condition. Provide separate combination of power Supply and battery enclosure when large batteries are required and not be able embedded inside FACP panel.
A16: Detection and initiation devices
A17: Supply, installation, testing and commissioning of intelligent, addressable type fire alarm detectors and initiating devices as shown on the Contract drawings and specified in the Contract documents complete with all mounting accessories including boxes, connectors and terminations.
A18: Smoke detector - photoelectric, addressable, self diagnostic, self address | B18: 747 | C18: Ea | D18: 339.5 | E18: 672.3 | F18: =B18-E18 -> 74.7 | G18: =E18+F18 -> 747 | H18: =E18*D18 -> 228245.85 | I18: =F18*D18 -> 25360.65 | J18: =H18+I18 -> 253606.5 | K18: =G18/B18 -> 1 | L18: 120 | M18: 80 | N18: =B18*(L18+M18) -> 149400 | O18: =J18-N18 -> 104206.5
A19: Heat detector - rate of rise type with fix temperature | B19: 36 | C19: Ea | D19: 339.5 | E19: 32.4 | F19: =B19-E19 -> 3.6 | G19: =E19+F19 -> 36 | H19: =E19*D19 -> 10999.8 | I19: =F19*D19 -> 1222.2 | J19: =H19+I19 -> 12222 | K19: =G19/B19 -> 1 | L19: 110 | M19: 80 | N19: =B19*(L19+M19) -> 6840 | O19: =J19-N19 -> 5382
A20: Addressable manual fire alarm pull station | B20: 72 | C20: Ea | D20: 291 | E20: 64.8 | F20: =B20-E20 -> 7.2 | G20: =E20+F20 -> 72 | H20: =E20*D20 -> 18856.8 | I20: =F20*D20 -> 2095.2 | J20: =H20+I20 -> 20952 | K20: =G20/B20 -> 1 | L20: 160 | M20: 80 | N20: =B20*(L20+M20) -> 17280 | O20: =J20-N20 -> 3672
A21: Addressable manual fire alarm pull station, weather proof | B21: 27 | C21: Ea | D21: 368.6 | E21: 24.21 | F21: =B21-E21 -> 2.79 | G21: =E21+F21 -> 27 | H21: =E21*D21 -> 8923.806 | I21: =F21*D21 -> 1028.394 | J21: =H21+I21 -> 9952.2 | K21: =G21/B21 -> 1 | L21: 180 | M21: 80 | N21: =B21*(L21+M21) -> 7020 | O21: =J21-N21 -> 2932.2
A22: Other initiating devices and control devices
A23: Supply, Installation, testing and commissioning of all conventional I/O interfaces devices for interface and Integration with firefighting systems, gas alarm and control systems, lift safety devices, fire water pumps, HVAC systems. elevators and all other specified equipment as per contract drawings and specifications, complete with all mounting accessories including boxes and terminations.
A24: Fire alarm monitoring module (MM) | B24: 24 | C24: Ea | D24: 436.5 | E24: 21.52 | F24: =B24-E24 -> 2.48 | G24: =E24+F24 -> 24 | H24: =E24*D24 -> 9393.48 | I24: =F24*D24 -> 1082.52 | J24: =H24+I24 -> 10476 | K24: =G24/B24 -> 1 | L24: 140 | M24: 80 | N24: =B24*(L24+M24) -> 5280 | O24: =J24-N24 -> 5196
A25: Notification appliances
A26: Supply, installation, testing and commissioning of visual and sound alarm devices as shown on the Contract drawings and specified in the Contract documents complete with all mounting accessories including boxes and terminations.
A27: Bells, indoor with strobe lights / beacons - red body, red lens for fire alarm | B27: 84 | C27: Ea | D27: 388 | E27: 75.6 | F27: =B27-E27 -> 8.4 | G27: =E27+F27 -> 84 | H27: =E27*D27 -> 29332.8 | I27: =F27*D27 -> 3259.2 | J27: =H27+I27 -> 32592 | K27: =G27/B27 -> 1 | L27: 212 | M27: 80 | N27: =B27*(L27+M27) -> 24528 | O27: =J27-N27 -> 8064
A28: Bells, indoor with strobe lights / beacons - red body, red lens for fire alarm, weather proof | B28: 39 | C28: Ea | D28: 436.5 | E28: 34.97 | F28: =B28-E28 -> 4.03 | G28: =E28+F28 -> 39 | H28: =E28*D28 -> 15264.405 | I28: =F28*D28 -> 1759.095 | J28: =H28+I28 -> 17023.5 | K28: =G28/B28 -> 1 | L28: 250 | M28: 80 | N28: =B28*(L28+M28) -> 12870 | O28: =J28-N28 -> 4153.5
A29: Fire alarm cables - fire resistant cable, 300V/500V, red sheath with low emission of smoke, halogen free, thermoplastic material
A30: To include for the procurement, supply, factory testing, delivery to Site, installation, testing and commissioning of the cables, termination materials and all cable support and wiring, identification accessories.
A31: 2C x 2.5 mm², Stranded plain copper wire or solid conductor, overall shield with drain wire for SLC loop | B31: 3915 | C31: m | D31: 24.25 | E31: 3706.2 | F31: =B31-E31 -> 208.8 | G31: =E31+F31 -> 3915 | H31: =E31*D31 -> 89875.35 | I31: =F31*D31 -> 5063.4 | J31: =H31+I31 -> 94938.75 | K31: =G31/B31 -> 1 | L31: 8 | M31: 0 | N31: =B31*(L31+M31) -> 31320 | O31: =J31-N31 -> 63618.75
A32: 2C x 2.5 mm², Stranded plain copper wire or solid conductor, overall shield with drain wire for NAC Loop | B32: 1845 | C32: m | D32: 24.25 | E32: 1757 | F32: =B32-E32 -> 88 | G32: =E32+F32 -> 1845 | H32: =E32*D32 -> 42607.25 | I32: =F32*D32 -> 2134 | J32: =H32+I32 -> 44741.25 | K32: =G32/B32 -> 1 | L32: 8 | M32: 0 | N32: =B32*(L32+M32) -> 14760 | O32: =J32-N32 -> 29981.25
A33: Fire alarm cable conduit, all JB boxes, fittings and accessories for cable installations
A34: To include for the procurement, supply, installation of PVC conduits and flexible metallic conduits for fire cables, junction boxes, fittings, accessories and all other relevant items or Works to complete fully Fire alarm detection system installations.
A35: 20 mm diameter, PVC conduits | B35: 0 | C35: m | D35: 24.25 | E35: 0 | F35: =(B35*(0.4+0.125)) -> 0 | G35: =E35+F35 -> 0 | H35: =E35*D35 -> 0 | I35: =F35*D35 -> 0 | J35: =H35+I35 -> 0 | N35: =B35*(L35+M35) -> 0 | O35: =J35-N35 -> 0
A36: SUB-TOTAL ITEM NO. B1-28 00 00 | B36: xxx | C36: xxx | H36: =SUM(H13:H35) -> 699685.54 | I36: =SUM(I13:I35) -> 122738.66 | J36: =SUM(J12:J35) -> 822424.2 | N36: =SUM(N12:N35) -> 473058 | O36: =SUM(O12:O35) -> 349366.2
A37: (TO BE CARRIED TO COMPOSITE SUMMARY)
A39: OWNER | B39: CONSULTANT | H39: CONTRACTOR

Sheet JUN-T1-EXT
C5: JUN-T1
A6: SECTION 2- SCHEDULE OF QUANTITIES AND PRICES | C6: B O Q | F6: THE ACTUAL QTY | I6: AMOUNT (SR) | L6: Percentage
A7: PAY ITEM NO. | B7: DESCRIPTION OF ITEM | C7: ESTIMATED QUANTITY | D7: UNIT | E7: UNIT PRICE(SR) EXCL. VAT | F7: Previous QTY | G7: Current QTY | H7: Cumulative QTY | I7: Previous | J7: Current | K7: Cumulative | M7: Actual price | N7: Actual Labour charge | O7: Total AP+LC | P7: Profit
B8: DIVISION 10 - SPECIALTIES
A9: 1.0 | B9: Fire Extinguishers
B10: Includes mounting brackets, fasteners, service tags, fully charged and ready to use extinguishers.
A11: a. | B11: Multipurpose dry chemical type, UL rated ABC
A12: a.1 | B12: FE-1, 6 kg, multi purpose fire extinguisher | C12: 96 | D12: Ea | E12: 242.5 | F12: 96 | G12: 0 | H12: =F12+G12 -> 96 | I12: =E12*F12 -> 23280 | J12: =G12*E12 -> 0 | K12: =I12+J12 -> 23280 | L12: =H12/C12 -> 1 | M12: 240 | N12: 10 | O12: =C12*(M12+N12) -> 24000 | P12: =K12-O12 -> -720
A13: b. | B13: Wet chemical type, UL rated class K
A14: b.1 | B14: FE-3, kitchen type-K fire extinguisher 2 gallon | C14: 36 | D14: Ea | E14: 533.5 | F14: 36 | G14: 0 | H14: =F14+G14 -> 36 | I14: =E14*F14 -> 19206 | J14: =G14*E14 -> 0 | K14: =I14+J14 -> 19206 | L14: =H14/C14 -> 1 | M14: 320 | N14: 10 | O14: =C14*(M14+N14) -> 11880 | P14: =K14-O14 -> 7326
A15: c. | B15: Automatic fire extinguisher
A16: c.1 | B16: FE-2, 12 kg, multi purpose fire extinguisher, ceiling mounted | C16: 48 | D16: Ea | E16: 485 | F16: 48 | G16: 0 | H16: =F16+G16 -> 48 | I16: =E16*F16 -> 23280 | J16: =G16*E16 -> 0 | K16: =I16+J16 -> 23280 | L16: =H16/C16 -> 1 | M16: 304 | N16: 10 | O16: =C16*(M16+N16) -> 15072 | P16: =K16-O16 -> 8208
A17: d. | B17: Fire blanket
B18: Supply and installation of fire blanket of specified type to be located in kitchen with all fittings and supports required to provide satisfactory operation.
A19: d.1 | B19: Fire blanket, standard size (1.2 meter x 1.2 meter), NFPA approved | C19: 36 | D19: Ea | E19: 291 | F19: 36 | G19: 0 | H19: =F19+G19 -> 36 | I19: =E19*F19 -> 10476 | J19: =G19*E19 -> 0 | K19: =I19+J19 -> 10476 | L19: =H19/C19 -> 1 | M19: 16 | N19: 10 | O19: =C19*(M19+N19) -> 936 | P19: =K19-O19 -> 9540
B20: SUB-TOTAL ITEM NO. B1-10 00 00 | C20: xxx | D20: xxx | I20: =SUM(I9:I19) -> 76242 | J20: =SUM(J9:J19) -> 0 | K20: =SUM(K9:K19) -> 76242 | O20: =SUM(O9:O19) -> 51888 | P20: =SUM(P9:P19) -> 24354

Sheet JUN-T1
C3: JUN T1
A4: SECTION 2- SCHEDULE OF QUANTITIES AND PRICES | C4: B O Q | F4: THE ACTUAL QTY | I4: AMOUNT (SR) | L4: Percentage
A5: PAY ITEM NO. | B5: DESCRIPTION OF ITEM | C5: ESTIMATED QUANTITY | D5: UNIT | E5: UNIT PRICE(SR) EXCL. VAT | F5: Previous QTY | G5: Current QTY | H5: Cumulative QTY | I5: Previous | J5: Current | K5: Cumulative | M5: Actual price | N5: accessories | O5: Actual Labour charge | P5: Total AP+LC | Q5: Profit
B6: DIVISION 21 - FIRE SUPPRESSION
A7: 1.0 | B7: General-Duty Valves for Water-Based Fire-Suppression Piping
B8: Supply and installation of valves including all fixings, supports, all other accessories and associated Works.
A9: a. | B9: Gate valve, UL and FM global approved
A10: a.1 | B10: 150 mm diameter | C10: 6 | D10: Ea | E10: 3686 | F10: 5.2 | G10: =C10-F10 -> 0.8 | H10: =F10+G10 -> 6 | I10: =E10*F10 -> 19167.2 | J10: =G10*E10 -> 2948.8 | K10: =I10+J10 -> 22116 | L10: =H10/C10 -> 1 | M10: 1250 | N10: 100 | O10: 300 | P10: =C10*(M10+N10+O10) -> 9900 | Q10: =K10-P10 -> 12216
A11: b. | B11: Alarm check valve, UL and FM global approved
A12: b.1 | B12: 150 mm diameter | C12: 3 | D12: Ea | E12: 5577.5 | F12: 2.3 | G12: =C12-F12 -> 0.7 | H12: =F12+G12 -> 3 | I12: =E12*F12 -> 12828.25 | J12: =G12*E12 -> 3904.25 | K12: =I12+J12 -> 16732.5 | L12: =H12/C12 -> 1 | M12: 3830 | N12: 200 | O12: 100 | P12: =C12*(M12+N12+O12) -> 12390 | Q12: =K12-P12 -> 4342.5
A13: c. | B13: Zone control valve assembly
A14: c.1 | B14: 100 mm diameter | C14: 9 | D14: Ea | E14: 5626 | F14: 7.8 | G14: =C14-F14 -> 1.2 | H14: =F14+G14 -> 9 | I14: =E14*F14 -> 43882.8 | J14: =G14*E14 -> 6751.2 | K14: =I14+J14 -> 50634 | L14: =H14/C14 -> 1 | M14: 3000 | N14: 150 | O14: 100 | P14: =C14*(M14+N14+O14) -> 29250 | Q14: =K14-P14 -> 21384
A15: 2.0 | B15: Fire-Department Connections
B16: Two way, swivel fittings, Dust caps and chains of same material as body, chrome plated finish and threads to match local fire department hardware
A17: a. | B17: Flush wall mounted fire department connection with check valve
A18: a.1 | B18: Two-way swivel fittings, 65 x 65 x 100 mm single clapper Siamese-type connections | C18: 3 | D18: Ea | E18: 4462 | F18: 1.95 | G18: =C18-F18 -> 1.05 | H18: =F18+G18 -> 3 | I18: =E18*F18 -> 8700.9 | J18: =G18*E18 -> 4685.1 | K18: =I18+J18 -> 13386 | L18: =H18/C18 -> 1 | M18: 450 | N18: 150 | O18: 100 | P18: =C18*(M18+N18+O18) -> 2100 | Q18: =K18-P18 -> 11286
A19: 3.0 | B19: Wet-Pipe Sprinkler Systems
A20: a. | B20: Black steel fire water pipes
B21: Supply and installation of black steel pipe seamless type as per ASTM A53 including supports, hangers, fixing, fitting, all other accessories and associated Works as per Contract drawings and specifications.
A22: a.1 | B22: 25 mm diameter | C22: 2550 | D22: m | E22: 53.35 | F22: 2550 | G22: =C22-F22 -> 0 | H22: =F22+G22 -> 2550 | I22: =E22*F22 -> 136042.5 | J22: =G22*E22 -> 0 | K22: =I22+J22 -> 136042.5 | L22: =(H22/C22) -> 1 | M22: 15 | N22: 7.5 | O22: 0 | P22: =C22*(M22+N22+O22) -> 57375 | Q22: =K22-P22 -> 78667.5
A23: a.2 | B23: 32 mm diameter | C23: 375 | D23: m | E23: 63.05 | F23: 375 | G23: =C23-F23 -> 0 | H23: =F23+G23 -> 375 | I23: =E23*F23 -> 23643.75 | J23: =G23*E23 -> 0 | K23: =I23+J23 -> 23643.75 | L23: =(H23/C23) -> 1 | M23: 20 | N23: 10 | O23: 0 | P23: =C23*(M23+N23+O23) -> 11250 | Q23: =K23-P23 -> 12393.75
A24: a.3 | B24: 40 mm diameter | C24: 276 | D24: m | E24: 77.6 | F24: 276 | G24: =C24-F24 -> 0 | H24: =F24+G24 -> 276 | I24: =E24*F24 -> 21417.6 | J24: =G24*E24 -> 0 | K24: =I24+J24 -> 21417.6 | L24: =(H24/C24) -> 1 | M24: 24 | N24: 12 | O24: 0 | P24: =C24*(M24+N24+O24) -> 9936 | Q24: =K24-P24 -> 11481.6
A25: a.4 | B25: 50 mm diameter | C25: 90 | D25: m | E25: 95.06 | F25: 90 | G25: =C25-F25 -> 0 | H25: =F25+G25 -> 90 | I25: =E25*F25 -> 8555.4 | J25: =G25*E25 -> 0 | K25: =I25+J25 -> 8555.4 | L25: =(H25/C25) -> 1 | M25: 28 | N25: 14 | O25: 0 | P25: =C25*(M25+N25+O25) -> 3780 | Q25: =K25-P25 -> 4775.4
A26: a.5 | B26: 65 mm diameter | C26: 30 | D26: m | E26: 169.75 | F26: 30 | G26: =C26-F26 -> 0 | H26: =F26+G26 -> 30 | I26: =E26*F26 -> 5092.5 | J26: =G26*E26 -> 0 | K26: =I26+J26 -> 5092.5 | L26: =(H26/C26) -> 1 | M26: 30 | N26: 15 | O26: 0 | P26: =C26*(M26+N26+O26) -> 1350 | Q26: =K26-P26 -> 3742.5
A27: a.6 | B27: 80 mm diameter | C27: 30 | D27: m | E27: 190.12 | F27: 30 | G27: =C27-F27 -> 0 | H27: =F27+G27 -> 30 | I27: =E27*F27 -> 5703.6 | J27: =G27*E27 -> 0 | K27: =I27+J27 -> 5703.6 | L27: =(H27/C27) -> 1 | M27: 35 | N27: 25 | O27: 0 | P27: =C27*(M27+N27+O27) -> 1800 | Q27: =K27-P27 -> 3903.6
A28: a.7 | B28: 100 mm diameter | C28: 450 | D28: m | E28: 237.65 | F28: 450 | G28: =C28-F28 -> 0 | H28: =F28+G28 -> 450 | I28: =E28*F28 -> 106942.5 | J28: =G28*E28 -> 0 | K28: =I28+J28 -> 106942.5 | L28: =(H28/C28) -> 1 | M28: 90 | N28: 60 | O28: 0 | P28: =C28*(M28+N28+O28) -> 67500 | Q28: =K28-P28 -> 39442.5
A29: a.8 | B29: 150 mm diameter | C29: 120 | D29: m | E29: 344.35 | F29: 120 | G29: =C29-F29 -> 0 | H29: =F29+G29 -> 120 | I29: =E29*F29 -> 41322 | J29: =G29*E29 -> 0 | K29: =I29+J29 -> 41322 | L29: =(H29/C29) -> 1 | M29: 170 | N29: 90 | O29: 0 | P29: =C29*(M29+N29+O29) -> 31200 | Q29: =K29-P29 -> 10122
A30: b. | B30: Fire water sprinkler head
B31: Sprinkler Head, UL listed FM approved, chrome-plated, bronze and factory painted; Shall be of one manufacturer. (No mixing of sprinkler brands shall be permitted).
A32: b.1 | B32: Pendent type | C32: 750 | D32: Ea | E32: 63.05 | F32: 651.95 | G32: =C32-F32 -> 98.05 | H32: =F32+G32 -> 750 | I32: =E32*F32 -> 41105.448 | J32: =G32*E32 -> 6182.0525 | K32: =I32+J32 -> 47287.5 | L32: =H32/C32 -> 1 | M32: 25 | N32: 5 | O32: 100 | P32: =C32*(M32+N32+O32) -> 97500 | Q32: =K32-P32 -> -50212.5
A33: b.2 | B33: Upright type | C33: 48 | D33: Ea | E33: 33.95 | F33: 41.6 | G33: =C33-F33 -> 6.4 | H33: =F33+G33 -> 48 | I33: =E33*F33 -> 1412.32 | J33: =G33*E33 -> 217.28 | K33: =I33+J33 -> 1629.6 | L33: =H33/C33 -> 1 | M33: 19 | N33: 5 | O33: 100 | P33: =C33*(M33+N33+O33) -> 5952 | Q33: =K33-P33 -> -4322.4
A34: b.3 | B34: Wall side type | C34: 456 | D34: Ea | E34: 72.75 | F34: 395.2 | G34: =C34-F34 -> 60.8 | H34: =F34+G34 -> 456 | I34: =E34*F34 -> 28750.8 | J34: =G34*E34 -> 4423.2 | K34: =I34+J34 -> 33174 | L34: =H34/C34 -> 1 | M34: 59 | N34: 5 | O34: 100 | P34: =C34*(M34+N34+O34) -> 74784 | Q34: =K34-P34 -> -41610
A35: 4.0 | B35: Fire-Suppression Standpipes
A36: a. | B36: Fire Hose Cabinet
B37: Supply and installation of Surface mounted fire hose Cabinets Made of Stainless Steel, dimension (W 750 x H 850 x D 180). with Synthetic Single Jacket Hose 1.5” x 30 meter long and (1) multipurpose dry powder Extinguisher include fittings, joints, unions, dielectric fittings, flanges, gaskets, grooved mechanical couplings, nuts and bolts, hangers and supports and labelling.
A38: a.1 | B38: FHC-II | C38: 48 | D38: Ea | E38: 4704.5 | F38: 48 | G38: 0 | H38: =F38+G38 -> 48 | I38: =E38*F38 -> 225816 | J38: =G38*E38 -> 0 | K38: =I38+J38 -> 225816 | L38: =H38/C38 -> 1 | M38: 4200 | N38: 250 | O38: 400 | P38: =C38*(M38+N38+O38) -> 232800 | Q38: =K38-P38 -> -6984
B39: SUB-TOTAL ITEM NO. B1-21 00 00 | C39: xxx | D39: xxx | I39: =SUM(I9:I38) -> 730383.57 | J39: =SUM(J9:J38) -> 29111.882 | K39: =SUM(K9:K38) -> 759495.45 | P39: =SUM(P9:P38) -> 648867 | Q39: =SUM(Q9:Q38) -> 110628.45
B40: (TO BE CARRIED TO COMPOSITE SUMMARY)
B42: OWNER | C42: CONSULTANT | I42: CONTRACTOR

Sheet JUN-T2 E
B3: JUN T2 - E
B4: B O Q | E4: THE ACTUAL QTY | H4: AMOUNT (SR)
A5: DESCRIPTION OF ITEM | B5: ESTIMATED QUANTITY | C5: UNIT | D5: UNIT PRICE(SR) EXCL. VAT | E5: Previous QTY | F5: Current QTY | G5: Cumulative QTY | H5: Previous | I5: Current | J5: Cumulative | K5: Percentage | L5: Actual price | M5: Actual Labour charge | N5: Total AP+LC | O5: Profit
A7: DIVISION 28-ELECTRONIC SAFETY AND SECURITY
A8: Supply and installation of IP Fixed cameras, POE+ TCP/IP and IP Indoor fixed mini dome camera-ceiling mounted, including all accessories, testing, commissioning and configuration of the network and other Works as shown on the Contract drawings and specified in the Contract documents.
A9: Fire Detection and Alarm
A10: Fire alarm control panel (FACP)
A11: Supply, installation, testing and commissioning of a microprocessor based, addressable fire alarm control panel, complete with Chassis, 640-Character backlit LCD display, QWERTY programming and control keypad, loop cards, zone and input/output modules, supervisory devices, auxiliary relays, network capability modules, battery, battery charger, printer, internal alarm, interface contacts and all accessories and hardware as shown on the Contract drawings and specified in the Contract documents and to complete the fully functional, operable, reliable and maintainable fire alarm system.
A12: Microprocessor based, addressable FACP,5 loop type | B12: 2 | C12: Ea | D12: 22795 | E12: 1.8 | F12: =B12-E12 -> 0.2 | G12: =E12+F12 -> 2 | H12: =D12*E12 -> 41031 | I12: =D12*F12 -> 4559 | J12: =H12+I12 -> 45590 | K12: =G12/B12 -> 1 | L12: 16900 | M12: 80 | N12: =B12*(L12+M12) -> 33960 | O12: =J12-N12 -> 11630
A13: Power supply unit, batteries and battery chargers | B13: 2 | C13: Ea | D13: 4365 | E13: 0 | F13: =B13-E13 -> 2 | G13: =E13+F13 -> 2 | H13: =D13*E13 -> 0 | I13: =D13*F13 -> 8730 | J13: =H13+I13 -> 8730 | K13: =G13/B13 -> 1 | L13: 0 | M13: 0 | N13: =B13*(L13+M13) -> 0 | O13: =J13-N13 -> 8730
A14: Supply, selection and calculation, installation, testing and commissioning of FACP power supply unit, batteries for at least 24 hours during the normal operations and 15 mins under emergency full loaded condition. Provide separate combination of power Supply and battery enclosure when large batteries are required and not be able embedded inside FACP panel.
A15: Detection and initiation devices
A16: Supply, installation, testing and commissioning of intelligent, addressable type fire alarm detectors and initiating devices as shown on the Contract drawings and specified in the Contract documents complete with all mounting accessories including boxes, connectors and terminations.
A17: Smoke detector - photoelectric, addressable, self diagnostic, self address | B17: 244 | C17: Ea | D17: 339.5 | E17: 219.6 | F17: =B17-E17 -> 24.4 | G17: =E17+F17 -> 244 | H17: =D17*E17 -> 74554.2 | I17: =D17*F17 -> 8283.8 | J17: =H17+I17 -> 82838 | K17: =G17/B17 -> 1 | L17: 120 | M17: 80 | N17: =B17*(L17+M17) -> 48800 | O17: =J17-N17 -> 34038
A18: Heat detector - rate of rise type with fix temperature | B18: 6 | C18: Ea | D18: 339.5 | E18: 5.4 | F18: =B18-E18 -> 0.6 | G18: =E18+F18 -> 6 | H18: =D18*E18 -> 1833.3 | I18: =D18*F18 -> 203.7 | J18: =H18+I18 -> 2037 | K18: =G18/B18 -> 1 | L18: 110 | M18: 80 | N18: =B18*(L18+M18) -> 1140 | O18: =J18-N18 -> 897
A19: Addressable manual fire alarm pull station | B19: 12 | C19: Ea | D19: 291 | E19: 10.8 | F19: =B19-E19 -> 1.2 | G19: =E19+F19 -> 12 | H19: =D19*E19 -> 3142.8 | I19: =D19*F19 -> 349.2 | J19: =H19+I19 -> 3492 | K19: =G19/B19 -> 1 | L19: 160 | M19: 80 | N19: =B19*(L19+M19) -> 2880 | O19: =J19-N19 -> 612
A20: Addressable manual fire alarm pull station, weather proof | B20: 4 | C20: Ea | D20: 368.6 | E20: 3.6 | F20: =B20-E20 -> 0.4 | G20: =E20+F20 -> 4 | H20: =D20*E20 -> 1326.96 | I20: =D20*F20 -> 147.44 | J20: =H20+I20 -> 1474.4 | K20: =G20/B20 -> 1 | L20: 180 | M20: 80 | N20: =B20*(L20+M20) -> 1040 | O20: =J20-N20 -> 434.4
A21: Other initiating devices and control devices | F21: =B21-E21 -> 0
A22: Supply, Installation, testing and commissioning of all conventional I/O interfaces devices for interface and Integration with firefighting systems, gas alarm and control systems, lift safety devices, fire water pumps, HVAC systems. elevators and all other specified equipment as per contract drawings and specifications, complete with all mounting accessories including boxes and terminations. | F22: =B22-E22 -> 0
A23: Fire alarm monitoring module (MM) | B23: 16 | C23: Ea | D23: 436.5 | E23: 14.4 | F23: =B23-E23 -> 1.6 | G23: =E23+F23 -> 16 | H23: =D23*E23 -> 6285.6 | I23: =D23*F23 -> 698.4 | J23: =H23+I23 -> 6984 | K23: =G23/B23 -> 1 | L23: 140 | M23: 80 | N23: =B23*(L23+M23) -> 3520 | O23: =J23-N23 -> 3464
A24: Notification appliances | F24: =B24-E24 -> 0
A25: Supply, installation, testing and commissioning of visual and sound alarm devices as shown on the Contract drawings and specified in the Contract documents complete with all mounting accessories including boxes and terminations. | F25: =B25-E25 -> 0
A26: Bells, indoor with strobe lights / beacons - red body, red lens for fire alarm | B26: 14 | C26: Ea | D26: 388 | E26: 12.6 | F26: =B26-E26 -> 1.4 | G26: =E26+F26 -> 14 | H26: =D26*E26 -> 4888.8 | I26: =D26*F26 -> 543.2 | J26: =H26+I26 -> 5432 | K26: =G26/B26 -> 1 | L26: 212 | M26: 80 | N26: =B26*(L26+M26) -> 4088 | O26: =J26-N26 -> 1344
A27: Bells, indoor with strobe lights / beacons - red body, red lens for fire alarm, weather proof | B27: 8 | C27: Ea | D27: 436.5 | E27: 7.2 | F27: =B27-E27 -> 0.8 | G27: =E27+F27 -> 8 | H27: =D27*E27 -> 3142.8 | I27: =D27*F27 -> 349.2 | J27: =H27+I27 -> 3492 | K27: =G27/B27 -> 1 | L27: 250 | M27: 80 | N27: =B27*(L27+M27) -> 2640 | O27: =J27-N27 -> 852
A28: Fire alarm cables - fire resistant cable, 300V/500V, red sheath with low emission of smoke, halogen free, thermoplastic material | F28: =B28-E28 -> 0
A29: To include for the procurement, supply, factory testing, delivery to Site, installation, testing and commissioning of the cables, termination materials and all cable support and wiring, identification accessories. | F29: =B29-E29 -> 0
A30: 2C x 2.5 mm², Stranded plain copper wire or solid conductor, overall shield with drain wire for SLC loop | B30: 1600 | C30: m | D30: 24.25 | E30: 1514.6667 | F30: =B30-E30 -> 85.333333 | G30: =E30+F30 -> 1600 | H30: =D30*E30 -> 36730.667 | I30: =D30*F30 -> 2069.3333 | J30: =H30+I30 -> 38800 | K30: =G30/B30 -> 1 | L30: 8 | M30: 0 | N30: =B30*(L30+M30) -> 12800 | O30: =J30-N30 -> 26000
A31: 2C x 2.5 mm², Stranded plain copper wire or solid conductor, overall shield with drain wire for NAC Loop | B31: 800 | C31: m | D31: 24.25 | E31: 757.33333 | F31: =B31-E31 -> 42.666667 | G31: =E31+F31 -> 800 | H31: =D31*E31 -> 18365.333 | I31: =D31*F31 -> 1034.6667 | J31: =H31+I31 -> 19400 | K31: =G31/B31 -> 1 | L31: 8 | M31: 0 | N31: =B31*(L31+M31) -> 6400 | O31: =J31-N31 -> 13000
A32: Fire alarm cable conduit, all JB boxes, fittings and accessories for cable installations
A33: To include for the procurement, supply, installation of PVC conduits and flexible metallic conduits for fire cables, junction boxes, fittings, accessories and all other relevant items or Works to complete fully Fire alarm detection system installations.
A34: 20 mm diameter, PVC conduits | B34: 0 | C34: m | D34: 24.25 | E34: 0 | F34: 0 | G34: =E34+F34 -> 0 | H34: =D34*E34 -> 0 | I34: =D34*F34 -> 0 | N34: =B34*(L34+M34) -> 0 | O34: =J34-N34 -> 0
A35: SUB-TOTAL ITEM NO. B1-28 00 00 | B35: xxx | C35: xxx | H35: =SUM(H12:H34) -> 191301.46 | I35: =SUM(I12:I34) -> 26967.94 | J35: =SUM(J12:J34) -> 218269.4 | N35: =SUM(N11:N34) -> 117268 | O35: =SUM(O11:O34) -> 101001.4
A36: (TO BE CARRIED TO COMPOSITE SUMMARY)
A38: OWNER | B38: CONSULTANT | H38: CONTRACTOR

Sheet JUN-T2-EXT
C5: JUN-T2
A6: SECTION 2- SCHEDULE OF QUANTITIES AND PRICES | C6: B O Q | F6: THE ACTUAL QTY | I6: AMOUNT (SR) | L6: Percentage
A7: PAY ITEM NO. | B7: DESCRIPTION OF ITEM | C7: ESTIMATED QUANTITY | D7: UNIT | E7: UNIT PRICE(SR) EXCL. VAT | F7: Previous QTY | G7: Current QTY | H7: Cumulative QTY | I7: Previous | J7: Current | K7: Cumulative | M7: Actual price | N7: Actual Labour charge | O7: Total AP+LC | P7: Profit
B8: DIVISION 10 - SPECIALTIES
A9: 1.0 | B9: Fire Extinguishers
B10: Includes mounting brackets, fasteners, service tags, fully charged and ready to use extinguishers.
A11: a. | B11: Multipurpose dry chemical type, UL rated ABC
A12: a.1 | B12: FE-1, 6 kg, multi purpose fire extinguisher | C12: 28 | D12: Ea | E12: 242.5 | F12: 21 | G12: =C12-F12 -> 7 | H12: =F12+G12 -> 28 | I12: =E12*F12 -> 5092.5 | J12: =G12*E12 -> 1697.5 | K12: =I12+J12 -> 6790 | L12: =H12/C12 -> 1 | M12: 240 | N12: 10 | O12: =C12*(M12+N12) -> 7000 | P12: =K12-O12 -> -210
A13: b. | B13: Wet chemical type, UL rated class K
A14: b.1 | B14: FE-3, kitchen type-K fire extinguisher 2 gallon | C14: 6 | D14: Ea | E14: 533.5 | F14: 3.9 | G14: =C14-F14 -> 2.1 | H14: =F14+G14 -> 6 | I14: =E14*F14 -> 2080.65 | J14: =G14*E14 -> 1120.35 | K14: =I14+J14 -> 3201 | L14: =H14/C14 -> 1 | M14: 320 | N14: 10 | O14: =C14*(M14+N14) -> 1980 | P14: =K14-O14 -> 1221
A15: c. | B15: Automatic fire extinguisher
A16: c.1 | B16: FE-2, 12 kg, multi purpose fire extinguisher, ceiling mounted | C16: 8 | D16: Ea | E16: 485 | F16: 5.2 | G16: =C16-F16 -> 2.8 | H16: =F16+G16 -> 8 | I16: =E16*F16 -> 2522 | J16: =G16*E16 -> 1358 | K16: =I16+J16 -> 3880 | L16: =H16/C16 -> 1 | M16: 304 | N16: 10 | O16: =C16*(M16+N16) -> 2512 | P16: =K16-O16 -> 1368
A17: d. | B17: Fire blanket
B18: Supply and installation of fire blanket of specified type to be located in kitchen with all fittings and supports required to provide satisfactory operation.
A19: d.1 | B19: Fire blanket, standard size (1.2 meter x 1.2 meter), NFPA approved | C19: 6 | D19: Ea | E19: 291 | F19: 6 | G19: =C19-F19 -> 0 | H19: =F19+G19 -> 6 | I19: =E19*F19 -> 1746 | J19: =G19*E19 -> 0 | K19: =I19+J19 -> 1746 | L19: =H19/C19 -> 1 | M19: 16 | N19: 10 | O19: =C19*(M19+N19) -> 156 | P19: =K19-O19 -> 1590
B20: SUB-TOTAL ITEM NO. B2-10 00 00 | C20: xxx | D20: xxx | I20: =SUM(I9:I19) -> 11441.15 | J20: =SUM(J9:J19) -> 4175.85 | K20: =SUM(K9:K19) -> 15617 | O20: =SUM(O9:O19) -> 11648 | P20: =SUM(P9:P19) -> 3969

Sheet JUN-T2
C3: JUN-T2
A4: SECTION 2- SCHEDULE OF QUANTITIES AND PRICES | C4: B O Q | F4: THE ACTUAL QTY | I4: AMOUNT (SR)
A5: PAY ITEM NO. | B5: DESCRIPTION OF ITEM | C5: ESTIMATED QUANTITY | D5: UNIT | E5: UNIT PRICE(SR) EXCL. VAT | F5: Previous QTY | G5: Current QTY | H5: Cumulative QTY | I5: Previous | J5: Current | K5: Cumulative | L5: Percentage | M5: Actual price | N5: accessories | O5: Actual Labour charge | P5: Total AP+LC | Q5: Profit
B6: DIVISION 21 - FIRE SUPPRESSION
A7: 1.0 | B7: General-Duty Valves for Water-Based Fire-Suppression Piping
B8: Supply and installation of valves including all fixings, supports, all other accessories and associated Works.
A9: a. | B9: Gate valve, UL and FM global approved
A10: a.1 | B10: 150 mm diameter | C10: 4 | D10: Ea | E10: 3686 | F10: 3.6 | G10: =C10-F10 -> 0.4 | H10: =F10+G10 -> 4 | I10: =E10*F10 -> 13269.6 | J10: =G10*E10 -> 1474.4 | K10: =I10+J10 -> 14744 | L10: =H10/C10 -> 1 | M10: 1250 | N10: 100 | O10: 300 | P10: =C10*(M10+N10+O10) -> 6600 | Q10: =K10-P10 -> 8144
A11: b. | B11: Alarm check valve, UL and FM global approved
A12: b.1 | B12: 150 mm diameter | C12: 2 | D12: Ea | E12: 5577.5 | F12: 1.8 | G12: =C12-F12 -> 0.2 | H12: =F12+G12 -> 2 | I12: =E12*F12 -> 10039.5 | J12: =G12*E12 -> 1115.5 | K12: =I12+J12 -> 11155 | L12: =H12/C12 -> 1 | M12: 3830 | N12: 200 | O12: 100 | P12: =C12*(M12+N12+O12) -> 8260 | Q12: =K12-P12 -> 2895
A13: c. | B13: Zone control valve assembly | G13: =C13-F13 -> 0
A14: c.1 | B14: 100 mm diameter | C14: 12 | D14: Ea | E14: 5626 | F14: 11.97 | G14: =C14-F14 -> 0.03 | H14: =F14+G14 -> 12 | I14: =E14*F14 -> 67343.22 | J14: =G14*E14 -> 168.78 | K14: =I14+J14 -> 67512 | L14: =H14/C14 -> 1 | M14: 3000 | N14: 150 | O14: 100 | P14: =C14*(M14+N14+O14) -> 39000 | Q14: =K14-P14 -> 28512
A15: 2.0 | B15: Fire-Department Connections | G15: =C15-F15 -> 0
B16: Two way, swivel fittings, Dust caps and chains of same material as body, chrome plated finish and threads to match local fire department hardware | G16: =C16-F16 -> 0
A17: a. | B17: Flush wall mounted fire department connection with check valve | G17: =C17-F17 -> 0
A18: a.1 | B18: Two-way swivel fittings, 65 x 65 x 100 mm single clapper Siamese-type connections | C18: 2 | D18: Ea | E18: 4462 | F18: 1.8 | G18: =C18-F18 -> 0.2 | H18: =F18+G18 -> 2 | I18: =E18*F18 -> 8031.6 | J18: =G18*E18 -> 892.4 | K18: =I18+J18 -> 8924 | L18: =H18/C18 -> 1 | M18: 450 | N18: 150 | O18: 100 | P18: =C18*(M18+N18+O18) -> 1400 | Q18: =K18-P18 -> 7524
A19: 3.0 | B19: Wet-Pipe Sprinkler Systems | G19: =C19-F19 -> 0
A20: a. | B20: Black steel fire water pipes | G20: =C20-F20 -> 0
B21: Supply and installation of black steel pipe seamless type as per ASTM A53 including supports, hangers, fixing, fitting, all other accessories and associated Works as per Contract drawings and specifications. | G21: =C21-F21 -> 0
A22: a.1 | B22: 25 mm diameter | C22: 520 | D22: m | E22: 53.35 | F22: 520 | G22: =C22-F22 -> 0 | H22: =F22+G22 -> 520 | I22: =E22*F22 -> 27742 | J22: =G22*E22 -> 0 | K22: =I22+J22 -> 27742 | L22: =(H22/C22) -> 1 | M22: 15 | N22: 7.5 | O22: 0 | P22: =C22*(M22+N22+O22) -> 11700 | Q22: =K22-P22 -> 16042
A23: a.2 | B23: 32 mm diameter | C23: 120 | D23: m | E23: 63.05 | F23: 120 | G23: =C23-F23 -> 0 | H23: =F23+G23 -> 120 | I23: =E23*F23 -> 7566 | J23: =G23*E23 -> 0 | K23: =I23+J23 -> 7566 | L23: =(H23/C23) -> 1 | M23: 20 | N23: 10 | O23: 0 | P23: =C23*(M23+N23+O23) -> 3600 | Q23: =K23-P23 -> 3966
A24: a.3 | B24: 40 mm diameter | C24: 20 | D24: m | E24: 77.6 | F24: 20 | G24: =C24-F24 -> 0 | H24: =F24+G24 -> 20 | I24: =E24*F24 -> 1552 | J24: =G24*E24 -> 0 | K24: =I24+J24 -> 1552 | L24: =(H24/C24) -> 1 | M24: 24 | N24: 12 | O24: 0 | P24: =C24*(M24+N24+O24) -> 720 | Q24: =K24-P24 -> 832
A25: a.4 | B25: 50 mm diameter | C25: 130 | D25: m | E25: 95.06 | F25: 130 | G25: =C25-F25 -> 0 | H25: =F25+G25 -> 130 | I25: =E25*F25 -> 12357.8 | J25: =G25*E25 -> 0 | K25: =I25+J25 -> 12357.8 | L25: =(H25/C25) -> 1 | M25: 28 | N25: 14 | O25: 0 | P25: =C25*(M25+N25+O25) -> 5460 | Q25: =K25-P25 -> 6897.8
A26: a.5 | B26: 63 mm diameter | C26: 190 | D26: m | E26: 169.75 | F26: 190 | G26: =C26-F26 -> 0 | H26: =F26+G26 -> 190 | I26: =E26*F26 -> 32252.5 | J26: =G26*E26 -> 0 | K26: =I26+J26 -> 32252.5 | L26: =(H26/C26) -> 1 | M26: 30 | N26: 15 | O26: 0 | P26: =C26*(M26+N26+O26) -> 8550 | Q26: =K26-P26 -> 23702.5
A27: a.6 | B27: 80 mm diameter | C27: 50 | D27: m | E27: 190.12 | F27: 50 | G27: =C27-F27 -> 0 | H27: =F27+G27 -> 50 | I27: =E27*F27 -> 9506 | J27: =G27*E27 -> 0 | K27: =I27+J27 -> 9506 | L27: =(H27/C27) -> 1 | M27: 35 | N27: 25 | O27: 0 | P27: =C27*(M27+N27+O27) -> 3000 | Q27: =K27-P27 -> 6506
A28: a.7 | B28: 100 mm diameter | C28: 30 | D28: m | E28: 237.65 | F28: 30 | G28: =C28-F28 -> 0 | H28: =F28+G28 -> 30 | I28: =E28*F28 -> 7129.5 | J28: =G28*E28 -> 0 | K28: =I28+J28 -> 7129.5 | L28: =(H28/C28) -> 1 | M28: 90 | N28: 60 | O28: 0 | P28: =C28*(M28+N28+O28) -> 4500 | Q28: =K28-P28 -> 2629.5
A29: a.8 | B29: 150 mm diameter | C29: 40 | D29: m | E29: 344.35 | F29: 40 | G29: =C29-F29 -> 0 | H29: =F29+G29 -> 40 | I29: =E29*F29 -> 13774 | J29: =G29*E29 -> 0 | K29: =I29+J29 -> 13774 | L29: =(H29/C29) -> 1 | M29: 170 | N29: 90 | O29: 0 | P29: =C29*(M29+N29+O29) -> 10400 | Q29: =K29-P29 -> 3374
A30: b. | B30: Fire water sprinkler head | G30: =C30-F30 -> 0
B31: Sprinkler Head, UL listed FM approved, chrome-plated, bronze and factory painted; Shall be of one manufacturer. (No mixing of sprinkler brands shall be permitted). | G31: =C31-F31 -> 0
A32: b.1 | B32: Pendent type | C32: 218 | D32: Ea | E32: 63.05 | F32: 196.2 | G32: =C32-F32 -> 21.8 | H32: =F32+G32 -> 218 | I32: =E32*F32 -> 12370.41 | J32: =G32*E32 -> 1374.49 | K32: =I32+J32 -> 13744.9 | L32: =H32/C32 -> 1 | M32: 25 | N32: 5 | O32: 100 | P32: =C32*(M32+N32+O32) -> 28340 | Q32: =K32-P32 -> -14595.1
A33: b.2 | B33: Upright type | C33: 8 | D33: Ea | E33: 33.95 | F33: 7.2 | G33: =C33-F33 -> 0.8 | H33: =F33+G33 -> 8 | I33: =E33*F33 -> 244.44 | J33: =G33*E33 -> 27.16 | K33: =I33+J33 -> 271.6 | L33: =H33/C33 -> 1 | M33: 19 | N33: 5 | O33: 100 | P33: =C33*(M33+N33+O33) -> 992 | Q33: =K33-P33 -> -720.4
A34: b.3 | B34: Wall side type | C34: 184 | D34: Ea | E34: 72.75 | F34: 165.6 | G34: =C34-F34 -> 18.4 | H34: =F34+G34 -> 184 | I34: =E34*F34 -> 12047.4 | J34: =G34*E34 -> 1338.6 | K34: =I34+J34 -> 13386 | L34: =H34/C34 -> 1 | M34: 59 | N34: 5 | O34: 100 | P34: =C34*(M34+N34+O34) -> 30176 | Q34: =K34-P34 -> -16790
A35: 4.0 | B35: Fire-Suppression Standpipes | G35: =C35-F35 -> 0
A36: a. | B36: Fire Hose Cabinet | G36: =C36-F36 -> 0
B37: Supply and installation of Surface mounted fire hose Cabinets Made of Stainless Steel, dimension (W 750 x H 850 x D 180). with Synthetic Single Jacket Hose 1.5” x 30 meter long and (1) multipurpose dry powder Extinguisher include fittings, joints, unions, dielectric fittings, flanges, gaskets, grooved mechanical couplings, nuts and bolts, hangers and supports and labelling. | G37: =C37-F37 -> 0
A38: a.1 | B38: FHC-II | C38: 12 | D38: Ea | E38: 4704.5 | F38: 12 | G38: =C38-F38 -> 0 | H38: =F38+G38 -> 12 | I38: =E38*F38 -> 56454 | J38: =G38*E38 -> 0 | K38: =I38+J38 -> 56454 | L38: =H38/C38 -> 1 | M38: 4200 | N38: 250 | O38: 400 | P38: =C38*(M38+N38+O38) -> 58200 | Q38: =K38-P38 -> -1746
B39: SUB-TOTAL ITEM NO. B2-21 00 00 | C39: xxx | D39: xxx | I39: =SUM(I9:I38) -> 291679.97 | J39: =SUM(J9:J38) -> 6391.33 | K39: =SUM(K9:K38) -> 298071.3 | P39: =SUM(P9:P38) -> 220898 | Q39: =SUM(Q9:Q38) -> 77173.3
B40: (TO BE CARRIED TO COMPOSITE SUMMARY)
B42: OWNER | C42: CONSULTANT | K42: CONTRACTOR

Sheet SUPERVISOR -E
B3: SUPERVISOR - E
B4: B O Q | E4: THE ACTUAL QTY | H4: AMOUNT (SR)
A5: DESCRIPTION OF ITEM | B5: ESTIMATED QUANTITY | C5: UNIT | D5: UNIT PRICE(SR) EXCL. VAT | E5: Previous QTY | F5: Current QTY | G5: Cumulative QTY | H5: Previous | I5: Current | J5: Cumulative | K5: Percentage | L5: Actual price | M5: Actual Labour charge | N5: Total AP+LC | O5: Profit
A6: DIVISION 28-ELECTRONIC SAFETY AND SECURITY
A7: Fire Detection and Alarm
A8: Fire alarm control panel (FACP)
A9: Supply, installation, testing and commissioning of a microprocessor based, addressable fire alarm control panel, complete with Chassis, 640-Character backlit LCD display, QWERTY programming and control keypad, loop cards, zone and input/output modules, supervisory devices, auxiliary relays, network capability modules, battery, battery charger, printer, internal alarm, interface contacts and all accessories and hardware as shown on the Contract drawings and specified in the Contract documents and to complete the fully functional, operable, reliable and maintainable fire alarm system.
A10: Microprocessor based, addressable FACP, 5 loop type | B10: 3 | C10: Ea | D10: 22795 | E10: 2.45 | F10: =B10-E10 -> 0.55 | G10: =E10+F10 -> 3 | H10: =E10*D10 -> 55847.75 | I10: =F10*D10 -> 12537.25 | J10: =H10+I10 -> 68385 | K10: =G10/B10 -> 1 | L10: 16900 | M10: 80 | N10: =B10*(L10+M10) -> 50940 | O10: =J10-N10 -> 17445
A11: Power supply unit, batteries and battery chargers | B11: 3 | C11: Ea | D11: 4365 | E11: 0 | F11: =B11-E11 -> 3 | G11: =E11+F11 -> 3 | H11: =E11*D11 -> 0 | I11: =F11*D11 -> 13095 | J11: =H11+I11 -> 13095 | K11: =G11/B11 -> 1 | L11: 0 | M11: 0 | N11: =B11*(L11+M11) -> 0 | O11: =J11-N11 -> 13095
A12: Supply, selection and calculation, installation, testing and commissioning of FACP power supply unit, batteries for at least 24 hours during the normal operations and 15 mins under emergency full loaded condition. Provide separate combination of power Supply and battery enclosure when large batteries are required and not be able embedded inside FACP panel. | N12: =B12*(L12+M12) -> 0 | O12: =J12-N12 -> 0
A13: Detection and initiation devices | N13: =B13*(L13+M13) -> 0 | O13: =J13-N13 -> 0
A14: Supply, installation, testing and commissioning of intelligent, addressable type fire alarm detectors and initiating devices as shown on the Contract drawings and specified in the Contract documents complete with all mounting accessories including boxes, connectors and terminations. | F14: =B14-E14 -> 0 | N14: =B14*(L14+M14) -> 0 | O14: =J14-N14 -> 0
A15: Smoke detector - photoelectric, addressable, self diagnostic, self address | B15: 420 | C15: Ea | D15: 339.5 | E15: 343 | F15: =B15-E15 -> 77 | G15: =E15+F15 -> 420 | H15: =E15*D15 -> 116448.5 | I15: =F15*D15 -> 26141.5 | J15: =H15+I15 -> 142590 | K15: =G15/B15 -> 1 | L15: 120 | M15: 80 | N15: =B15*(L15+M15) -> 84000 | O15: =J15-N15 -> 58590
A16: Heat detector - rate of rise type with fix temperature | B16: 9 | C16: Ea | D16: 339.5 | E16: 6.26 | F16: =B16-E16 -> 2.74 | G16: =E16+F16 -> 9 | H16: =E16*D16 -> 2125.27 | I16: =F16*D16 -> 930.23 | J16: =H16+I16 -> 3055.5 | K16: =G16/B16 -> 1 | L16: 110 | M16: 80 | N16: =B16*(L16+M16) -> 1710 | O16: =J16-N16 -> 1345.5
A17: Addressable manual fire alarm pull station | B17: 18 | C17: Ea | D17: 291 | E17: 14.7 | F17: =B17-E17 -> 3.3 | G17: =E17+F17 -> 18 | H17: =E17*D17 -> 4277.7 | I17: =F17*D17 -> 960.3 | J17: =H17+I17 -> 5238 | K17: =G17/B17 -> 1 | L17: 160 | M17: 80 | N17: =B17*(L17+M17) -> 4320 | O17: =J17-N17 -> 918
A18: Addressable manual fire alarm pull station, weather proof | B18: 6 | C18: Ea | D18: 368.6 | E18: 4.9 | F18: =B18-E18 -> 1.1 | G18: =E18+F18 -> 6 | H18: =E18*D18 -> 1806.14 | I18: =F18*D18 -> 405.46 | J18: =H18+I18 -> 2211.6 | K18: =G18/B18 -> 1 | L18: 180 | M18: 80 | N18: =B18*(L18+M18) -> 1560 | O18: =J18-N18 -> 651.6
A19: Other initiating devices and control devices | F19: =B19-E19 -> 0 | N19: =B19*(L19+M19) -> 0 | O19: =J19-N19 -> 0
A20: Supply, Installation, testing and commissioning of all conventional I/O interfaces devices for interface and Integration with firefighting systems, gas alarm and control systems, lift safety devices, fire water pumps, HVAC systems. elevators and all other specified equipment as per contract drawings and specifications, complete with all mounting accessories including boxes and terminations. | F20: =B20-E20 -> 0 | N20: =B20*(L20+M20) -> 0 | O20: =J20-N20 -> 0
A21: Fire alarm monitoring module (MM) | B21: 24 | C21: Ea | D21: 436.5 | E21: 19.6 | F21: =B21-E21 -> 4.4 | G21: =E21+F21 -> 24 | H21: =E21*D21 -> 8555.4 | I21: =F21*D21 -> 1920.6 | J21: =H21+I21 -> 10476 | K21: =G21/B21 -> 1 | L21: 140 | M21: 80 | N21: =B21*(L21+M21) -> 5280 | O21: =J21-N21 -> 5196
A22: Notification appliances | N22: =B22*(L22+M22) -> 0 | O22: =J22-N22 -> 0
A23: Supply, installation, testing and commissioning of visual and sound alarm devices as shown on the Contract drawings and specified in the Contract documents complete with all mounting accessories including boxes and terminations. | N23: =B23*(L23+M23) -> 0 | O23: =J23-N23 -> 0
A24: Bells, indoor with strobe lights / beacons - red body, red lens for fire alarm | B24: 21 | C24: Ea | D24: 388 | E24: 17.15 | F24: =B24-E24 -> 3.85 | G24: =E24+F24 -> 21 | H24: =E24*D24 -> 6654.2 | I24: =F24*D24 -> 1493.8 | J24: =H24+I24 -> 8148 | K24: =G24/B24 -> 1 | L24: 212 | M24: 80 | N24: =B24*(L24+M24) -> 6132 | O24: =J24-N24 -> 2016
A25: Bells, indoor with strobe lights / beacons - red body, red lens for fire alarm, weather proof | B25: 12 | C25: Ea | D25: 436.5 | E25: 9.8 | F25: =B25-E25 -> 2.2 | G25: =E25+F25 -> 12 | H25: =E25*D25 -> 4277.7 | I25: =F25*D25 -> 960.3 | J25: =H25+I25 -> 5238 | K25: =G25/B25 -> 1 | L25: 250 | M25: 80 | N25: =B25*(L25+M25) -> 3960 | O25: =J25-N25 -> 1278
A26: Fire alarm cables - fire resistant cable, 300V/500V, red sheath with low emission of smoke, halogen free, thermoplastic material | F26: =B26-E26 -> 0 | N26: =B26*(L26+M26) -> 0 | O26: =J26-N26 -> 0
A27: To include for the procurement, supply, factory testing, delivery to Site, installation, testing and commissioning of the cables, termination materials and all cable support and wiring, identification accessories. | F27: =B27-E27 -> 0 | N27: =B27*(L27+M27) -> 0 | O27: =J27-N27 -> 0
A28: 2C x 2.5 mm², Stranded plain copper wire or solid conductor, overall shield with drain wire for SLC loop | B28: 2400 | C28: m | D28: 24.25 | E28: 2280 | F28: =B28-E28 -> 120 | G28: =E28+F28 -> 2400 | H28: =E28*D28 -> 55290 | I28: =F28*D28 -> 2910 | J28: =H28+I28 -> 58200 | K28: =G28/B28 -> 1 | L28: 8 | M28: 0 | N28: =B28*(L28+M28) -> 19200 | O28: =J28-N28 -> 39000
A29: 2C x 2.5 mm², Stranded plain copper wire or solid conductor, overall shield with drain wire for NAC Loop | B29: 1200 | C29: m | D29: 24.25 | E29: 1140 | F29: =B29-E29 -> 60 | G29: =E29+F29 -> 1200 | H29: =E29*D29 -> 27645 | I29: =F29*D29 -> 1455 | J29: =H29+I29 -> 29100 | K29: =G29/B29 -> 1 | L29: 8 | M29: 0 | N29: =B29*(L29+M29) -> 9600 | O29: =J29-N29 -> 19500
A30: Fire alarm cable conduit, all JB boxes, fittings and accessories for cable installations | F30: =B30-E30 -> 0 | N30: =B30*(L30+M30) -> 0 | O30: =J30-N30 -> 0
A31: To include for the procurement, supply, installation of PVC conduits and flexible metallic conduits for fire cables, junction boxes, fittings, accessories and all other relevant items or Works to complete fully Fire alarm detection system installations. | F31: =B31-E31 -> 0 | N31: =B31*(L31+M31) -> 0 | O31: =J31-N31 -> 0
A32: 20 mm diameter, PVC conduits | B32: 0 | C32: m | D32: 24.25 | E32: 0 | F32: =B32-E32 -> 0 | G32: =E32+F32 -> 0 | H32: =E32*D32 -> 0 | I32: =F32*D32 -> 0 | J32: 0 | N32: =B32*(L32+M32) -> 0 | O32: =J32-N32 -> 0
A33: SUB-TOTAL ITEM NO. B1-28 00 00 | B33: xxx | C33: xxx | E33: 0 | F33: =B33-E33 -> #VALUE! | G33: =E33+F33 -> #VALUE! | H33: =SUM(H10:H32) -> 282927.66 | I33: =SUM(I10:I32) -> 62809.44 | J33: =SUM(J10:J32) -> 345737.1 | N33: =SUM(N9:N32) -> 186702 | O33: =SUM(O9:O32) -> 159035.1
A34: (TO BE CARRIED TO COMPOSITE SUMMARY)
A36: OWNER | B36: CONSULTANT | H36: CONTRACTOR

Sheet SUPERVISOR-EXT 
C5: SUPERVISOR
A6: SECTION 2- SCHEDULE OF QUANTITIES AND PRICES | C6: B O Q | F6: THE ACTUAL QTY | I6: AMOUNT (SR) | L6: Percentage
A7: PAY ITEM NO. | B7: DESCRIPTION OF ITEM | C7: ESTIMATED QUANTITY | D7: UNIT | E7: UNIT PRICE(SR) EXCL. VAT | F7: Previous QTY | G7: Current QTY | H7: Cumulative QTY | I7: Previous | J7: Current | K7: Cumulative | M7: Actual price | N7: Actual Labour charge | O7: Total AP+LC | P7: Profit
B8: DIVISION 10 - SPECIALTIES
A9: 1.0 | B9: Fire Extinguishers
B10: Includes mounting brackets, fasteners, service tags, fully charged and ready to use extinguishers.
A11: a. | B11: Multipurpose dry chemical type, UL rated ABC
A12: a.1 | B12: FE-1, 6 kg, multi purpose fire extinguisher | C12: 42 | D12: Ea | E12: 242.5 | F12: 32 | G12: =C12-F12 -> 10 | H12: =F12+G12 -> 42 | I12: =E12*F12 -> 7760 | J12: =G12*E12 -> 2425 | K12: =I12+J12 -> 10185 | L12: =H12/C12 -> 1 | M12: 240 | N12: 10 | O12: =C12*(M12+N12) -> 10500 | P12: =K12-O12 -> -315
A13: b. | B13: Wet chemical type, UL rated class K
A14: b.1 | B14: FE-3, kitchen type-K fire extinguisher 2 gallon | C14: 9 | D14: Ea | E14: 533.5 | F14: 5.85 | G14: =C14-F14 -> 3.15 | H14: =F14+G14 -> 9 | I14: =E14*F14 -> 3120.975 | J14: =G14*E14 -> 1680.525 | K14: =I14+J14 -> 4801.5 | L14: =H14/C14 -> 1 | M14: 320 | N14: 10 | O14: =C14*(M14+N14) -> 2970 | P14: =K14-O14 -> 1831.5
A15: c. | B15: Automatic fire extinguisher
A16: c.1 | B16: FE-2, 15 kg, multi purpose fire extinguisher, ceiling mounted | C16: 21 | D16: Ea | E16: 485 | F16: 13.65 | G16: =C16-F16 -> 7.35 | H16: =F16+G16 -> 21 | I16: =E16*F16 -> 6620.25 | J16: =G16*E16 -> 3564.75 | K16: =I16+J16 -> 10185 | L16: =H16/C16 -> 1 | M16: 334 | N16: 10 | O16: =C16*(M16+N16) -> 7224 | P16: =K16-O16 -> 2961
A17: d. | B17: Fire blanket
B18: Supply and installation of fire blanket of specified type to be located in kitchen with all fittings and supports required to provide satisfactory operation.
A19: d.1 | B19: Fire blanket, standard size (1.2 meter x 1.2 meter), NFPA approved | C19: 9 | D19: Ea | E19: 291 | F19: 9 | G19: =C19-F19 -> 0 | H19: =F19+G19 -> 9 | I19: =E19*F19 -> 2619 | J19: =G19*E19 -> 0 | K19: =I19+J19 -> 2619 | L19: =H19/C19 -> 1 | M19: 16 | N19: 10 | O19: =C19*(M19+N19) -> 234 | P19: =K19-O19 -> 2385
B20: SUB-TOTAL ITEM NO. B3-10 00 00 | C20: xxx | D20: xxx | I20: =SUM(I9:I19) -> 20120.225 | J20: =SUM(J9:J19) -> 7670.275 | K20: =SUM(K9:K19) -> 27790.5 | O20: =SUM(O9:O19) -> 20928 | P20: =SUM(P9:P19) -> 6862.5

Sheet SUPERVISOR
C3: SUPERVISOR
A4: SECTION 2- SCHEDULE OF QUANTITIES AND PRICES | C4: B O Q | F4: THE ACTUAL QTY | I4: AMOUNT (SR)
